Workbook

Sheet Summary
A1: WCAG evaluation results — condition comparison
A4: Overall accuracy by condition
A5: Condition | B5: Key | C5: Records | D5: Correct | E5: Accuracy | F5: Pass recall | G5: Fail recall | H5: Inapplicable recall | I5: Avg time (s) | J5: Avg issues | K5: Avg tool calls
A6: axe | B6: A | C6: =COUNTA(A_axe!$A$2:$A$538) -> 537 | D6: =SUM(A_axe!$I$2:$I$538) -> 237 | E6: =IFERROR(D6/C6,"") -> 0.44134078 | F6: =IFERROR(COUNTIFS(A_axe!$G$2:$G$538,"passed",A_axe!$I$2:$I$538,1)/COUNTIF(A_axe!$G$2:$G$538,"passed"),"") -> 0.95 | G6: =IFERROR(COUNTIFS(A_axe!$G$2:$G$538,"failed",A_axe!$I$2:$I$538,1)/COUNTIF(A_axe!$G$2:$G$538,"failed"),"") -> 0.37288136 | H6: =IFERROR(COUNTIFS(A_axe!$G$2:$G$538,"inapplicable",A_axe!$I$2:$I$538,1)/COUNTIF(A_axe!$G$2:$G$538,"inapplicable"),"") -> 0 | I6: =AVERAGE(A_axe!$P$2:$P$538) -> 12.687169 | J6: =AVERAGE(A_axe!$L$2:$L$538) -> 0.15083799 | K6: =AVERAGE(A_axe!$M$2:$M$538) -> 1
A7: persona_llm | B7: B | C7: =COUNTA(B_persona_llm!$A$2:$A$538) -> 537 | D7: =SUM(B_persona_llm!$I$2:$I$538) -> 381 | E7: =IFERROR(D7/C7,"") -> 0.70949721 | F7: =IFERROR(COUNTIFS(B_persona_llm!$G$2:$G$538,"passed",B_persona_llm!$I$2:$I$538,1)/COUNTIF(B_persona_llm!$G$2:$G$538,"passed"),"") -> 0.60555556 | G7: =IFERROR(COUNTIFS(B_persona_llm!$G$2:$G$538,"failed",B_persona_llm!$I$2:$I$538,1)/COUNTIF(B_persona_llm!$G$2:$G$538,"failed"),"") -> 0.94350282 | H7: =IFERROR(COUNTIFS(B_persona_llm!$G$2:$G$538,"inapplicable",B_persona_llm!$I$2:$I$538,1)/COUNTIF(B_persona_llm!$G$2:$G$538,"inapplicable"),"") -> 0.58333333 | I7: =AVERAGE(B_persona_llm!$P$2:$P$538) -> 7.538175 | J7: =AVERAGE(B_persona_llm!$L$2:$L$538) -> 1.1620112 | K7: =AVERAGE(B_persona_llm!$M$2:$M$538) -> 0
A8: persona_agent | B8: C | C8: =COUNTA(C_persona_agent!$A$2:$A$538) -> 537 | D8: =SUM(C_persona_agent!$I$2:$I$538) -> 284 | E8: =IFERROR(D8/C8,"") -> 0.52886406 | F8: =IFERROR(COUNTIFS(C_persona_agent!$G$2:$G$538,"passed",C_persona_agent!$I$2:$I$538,1)/COUNTIF(C_persona_agent!$G$2:$G$538,"passed"),"") -> 0.39444444 | G8: =IFERROR(COUNTIFS(C_persona_agent!$G$2:$G$538,"failed",C_persona_agent!$I$2:$I$538,1)/COUNTIF(C_persona_agent!$G$2:$G$538,"failed"),"") -> 0.86440678 | H8: =IFERROR(COUNTIFS(C_persona_agent!$G$2:$G$538,"inapplicable",C_persona_agent!$I$2:$I$538,1)/COUNTIF(C_persona_agent!$G$2:$G$538,"inapplicable"),"") -> 0.33333333 | I8: =AVERAGE(C_persona_agent!$P$2:$P$538) -> 28.47581 | J8: =AVERAGE(C_persona_agent!$L$2:$L$538) -> 0.84729981 | K8: =AVERAGE(C_persona_agent!$M$2:$M$538) -> 4.3389199
A9: vanilla_llm | B9: D | C9: =COUNTA(D_vanilla_llm!$A$2:$A$538) -> 537 | D9: =SUM(D_vanilla_llm!$I$2:$I$538) -> 370 | E9: =IFERROR(D9/C9,"") -> 0.68901304 | F9: =IFERROR(COUNTIFS(D_vanilla_llm!$G$2:$G$538,"passed",D_vanilla_llm!$I$2:$I$538,1)/COUNTIF(D_vanilla_llm!$G$2:$G$538,"passed"),"") -> 0.71111111 | G9: =IFERROR(COUNTIFS(D_vanilla_llm!$G$2:$G$538,"failed",D_vanilla_llm!$I$2:$I$538,1)/COUNTIF(D_vanilla_llm!$G$2:$G$538,"failed"),"") -> 0.96045198 | H9: =IFERROR(COUNTIFS(D_vanilla_llm!$G$2:$G$538,"inapplicable",D_vanilla_llm!$I$2:$I$538,1)/COUNTIF(D_vanilla_llm!$G$2:$G$538,"inapplicable"),"") -> 0.4 | I9: =AVERAGE(D_vanilla_llm!$P$2:$P$538) -> 9.8285847 | J9: =AVERAGE(D_vanilla_llm!$L$2:$L$538) -> 0.99255121 | K9: =AVERAGE(D_vanilla_llm!$M$2:$M$538) -> 0
A10: vanilla_agent | B10: E | C10: =COUNTA(E_vanilla_agent!$A$2:$A$538) -> 537 | D10: =SUM(E_vanilla_agent!$I$2:$I$538) -> 302 | E10: =IFERROR(D10/C10,"") -> 0.56238361 | F10: =IFERROR(COUNTIFS(E_vanilla_agent!$G$2:$G$538,"passed",E_vanilla_agent!$I$2:$I$538,1)/COUNTIF(E_vanilla_agent!$G$2:$G$538,"passed"),"") -> 0.39444444 | G10: =IFERROR(COUNTIFS(E_vanilla_agent!$G$2:$G$538,"failed",E_vanilla_agent!$I$2:$I$538,1)/COUNTIF(E_vanilla_agent!$G$2:$G$538,"failed"),"") -> 0.93220339 | H10: =IFERROR(COUNTIFS(E_vanilla_agent!$G$2:$G$538,"inapplicable",E_vanilla_agent!$I$2:$I$538,1)/COUNTIF(E_vanilla_agent!$G$2:$G$538,"inapplicable"),"") -> 0.36666667 | I10: =AVERAGE(E_vanilla_agent!$P$2:$P$538) -> 31.454879 | J10: =AVERAGE(E_vanilla_agent!$L$2:$L$538) -> 1.2290503 | K10: =AVERAGE(E_vanilla_agent!$M$2:$M$538) -> 4.4078212
A13: Confusion matrix — counts of evaluated label per expected label
A14: Condition | B14: Expected | C14: eval: passed | D14: eval: failed | E14: eval: inapplicable | F14: eval: error | G14: Total
A15: axe | B15: passed | C15: =COUNTIFS(A_axe!$G$2:$G$538,"passed",A_axe!$H$2:$H$538,"passed") -> 171 | D15: =COUNTIFS(A_axe!$G$2:$G$538,"passed",A_axe!$H$2:$H$538,"failed") -> 9 | E15: =COUNTIFS(A_axe!$G$2:$G$538,"passed",A_axe!$H$2:$H$538,"inapplicable") -> 0 | F15: =COUNTIFS(A_axe!$G$2:$G$538,"passed",A_axe!$H$2:$H$538,"error") -> 0 | G15: =SUM(C15:F15) -> 180
A16: axe | B16: failed | C16: =COUNTIFS(A_axe!$G$2:$G$538,"failed",A_axe!$H$2:$H$538,"passed") -> 111 | D16: =COUNTIFS(A_axe!$G$2:$G$538,"failed",A_axe!$H$2:$H$538,"failed") -> 66 | E16: =COUNTIFS(A_axe!$G$2:$G$538,"failed",A_axe!$H$2:$H$538,"inapplicable") -> 0 | F16: =COUNTIFS(A_axe!$G$2:$G$538,"failed",A_axe!$H$2:$H$538,"error") -> 0 | G16: =SUM(C16:F16) -> 177
A17: axe | B17: inapplicable | C17: =COUNTIFS(A_axe!$G$2:$G$538,"inapplicable",A_axe!$H$2:$H$538,"passed") -> 180 | D17: =COUNTIFS(A_axe!$G$2:$G$538,"inapplicable",A_axe!$H$2:$H$538,"failed") -> 0 | E17: =COUNTIFS(A_axe!$G$2:$G$538,"inapplicable",A_axe!$H$2:$H$538,"inapplicable") -> 0 | F17: =COUNTIFS(A_axe!$G$2:$G$538,"inapplicable",A_axe!$H$2:$H$538,"error") -> 0 | G17: =SUM(C17:F17) -> 180
A18: persona_llm | B18: passed | C18: =COUNTIFS(B_persona_llm!$G$2:$G$538,"passed",B_persona_llm!$H$2:$H$538,"passed") -> 109 | D18: =COUNTIFS(B_persona_llm!$G$2:$G$538,"passed",B_persona_llm!$H$2:$H$538,"failed") -> 46 | E18: =COUNTIFS(B_persona_llm!$G$2:$G$538,"passed",B_persona_llm!$H$2:$H$538,"inapplicable") -> 23 | F18: =COUNTIFS(B_persona_llm!$G$2:$G$538,"passed",B_persona_llm!$H$2:$H$538,"error") -> 2 | G18: =SUM(C18:F18) -> 180
A19: persona_llm | B19: failed | C19: =COUNTIFS(B_persona_llm!$G$2:$G$538,"failed",B_persona_llm!$H$2:$H$538,"passed") -> 6 | D19: =COUNTIFS(B_persona_llm!$G$2:$G$538,"failed",B_persona_llm!$H$2:$H$538,"failed") -> 167 | E19: =COUNTIFS(B_persona_llm!$G$2:$G$538,"failed",B_persona_llm!$H$2:$H$538,"inapplicable") -> 4 | F19: =COUNTIFS(B_persona_llm!$G$2:$G$538,"failed",B_persona_llm!$H$2:$H$538,"error") -> 0 | G19: =SUM(C19:F19) -> 177
A20: persona_llm | B20: inapplicable | C20: =COUNTIFS(B_persona_llm!$G$2:$G$538,"inapplicable",B_persona_llm!$H$2:$H$538,"passed") -> 54 | D20: =COUNTIFS(B_persona_llm!$G$2:$G$538,"inapplicable",B_persona_llm!$H$2:$H$538,"failed") -> 21 | E20: =COUNTIFS(B_persona_llm!$G$2:$G$538,"inapplicable",B_persona_llm!$H$2:$H$538,"inapplicable") -> 105 | F20: =COUNTIFS(B_persona_llm!$G$2:$G$538,"inapplicable",B_persona_llm!$H$2:$H$538,"error") -> 0 | G20: =SUM(C20:F20) -> 180
A21: persona_agent | B21: passed | C21: =COUNTIFS(C_persona_agent!$G$2:$G$538,"passed",C_persona_agent!$H$2:$H$538,"passed") -> 71 | D21: =COUNTIFS(C_persona_agent!$G$2:$G$538,"passed",C_persona_agent!$H$2:$H$538,"failed") -> 105 | E21: =COUNTIFS(C_persona_agent!$G$2:$G$538,"passed",C_persona_agent!$H$2:$H$538,"inapplicable") -> 4 | F21: =COUNTIFS(C_persona_agent!$G$2:$G$538,"passed",C_persona_agent!$H$2:$H$538,"error") -> 0 | G21: =SUM(C21:F21) -> 180
A22: persona_agent | B22: failed | C22: =COUNTIFS(C_persona_agent!$G$2:$G$538,"failed",C_persona_agent!$H$2:$H$538,"passed") -> 22 | D22: =COUNTIFS(C_persona_agent!$G$2:$G$538,"failed",C_persona_agent!$H$2:$H$538,"failed") -> 153 | E22: =COUNTIFS(C_persona_agent!$G$2:$G$538,"failed",C_persona_agent!$H$2:$H$538,"inapplicable") -> 2 | F22: =COUNTIFS(C_persona_agent!$G$2:$G$538,"failed",C_persona_agent!$H$2:$H$538,"error") -> 0 | G22: =SUM(C22:F22) -> 177
A23: persona_agent | B23: inapplicable | C23: =COUNTIFS(C_persona_agent!$G$2:$G$538,"inapplicable",C_persona_agent!$H$2:$H$538,"passed") -> 66 | D23: =COUNTIFS(C_persona_agent!$G$2:$G$538,"inapplicable",C_persona_agent!$H$2:$H$538,"failed") -> 54 | E23: =COUNTIFS(C_persona_agent!$G$2:$G$538,"inapplicable",C_persona_agent!$H$2:$H$538,"inapplicable") -> 60 | F23: =COUNTIFS(C_persona_agent!$G$2:$G$538,"inapplicable",C_persona_agent!$H$2:$H$538,"error") -> 0 | G23: =SUM(C23:F23) -> 180
A24: vanilla_llm | B24: passed | C24: =COUNTIFS(D_vanilla_llm!$G$2:$G$538,"passed",D_vanilla_llm!$H$2:$H$538,"passed") -> 128 | D24: =COUNTIFS(D_vanilla_llm!$G$2:$G$538,"passed",D_vanilla_llm!$H$2:$H$538,"failed") -> 45 | E24: =COUNTIFS(D_vanilla_llm!$G$2:$G$538,"passed",D_vanilla_llm!$H$2:$H$538,"inapplicable") -> 7 | F24: =COUNTIFS(D_vanilla_llm!$G$2:$G$538,"passed",D_vanilla_llm!$H$2:$H$538,"error") -> 0 | G24: =SUM(C24:F24) -> 180
A25: vanilla_llm | B25: failed | C25: =COUNTIFS(D_vanilla_llm!$G$2:$G$538,"failed",D_vanilla_llm!$H$2:$H$538,"passed") -> 4 | D25: =COUNTIFS(D_vanilla_llm!$G$2:$G$538,"failed",D_vanilla_llm!$H$2:$H$538,"failed") -> 170 | E25: =COUNTIFS(D_vanilla_llm!$G$2:$G$538,"failed",D_vanilla_llm!$H$2:$H$538,"inapplicable") -> 3 | F25: =COUNTIFS(D_vanilla_llm!$G$2:$G$538,"failed",D_vanilla_llm!$H$2:$H$538,"error") -> 0 | G25: =SUM(C25:F25) -> 177
A26: vanilla_llm | B26: inapplicable | C26: =COUNTIFS(D_vanilla_llm!$G$2:$G$538,"inapplicable",D_vanilla_llm!$H$2:$H$538,"passed") -> 51 | D26: =COUNTIFS(D_vanilla_llm!$G$2:$G$538,"inapplicable",D_vanilla_llm!$H$2:$H$538,"failed") -> 57 | E26: =COUNTIFS(D_vanilla_llm!$G$2:$G$538,"inapplicable",D_vanilla_llm!$H$2:$H$538,"inapplicable") -> 72 | F26: =COUNTIFS(D_vanilla_llm!$G$2:$G$538,"inapplicable",D_vanilla_llm!$H$2:$H$538,"error") -> 0 | G26: =SUM(C26:F26) -> 180
A27: vanilla_agent | B27: passed | C27: =COUNTIFS(E_vanilla_agent!$G$2:$G$538,"passed",E_vanilla_agent!$H$2:$H$538,"passed") -> 71 | D27: =COUNTIFS(E_vanilla_agent!$G$2:$G$538,"passed",E_vanilla_agent!$H$2:$H$538,"failed") -> 109 | E27: =COUNTIFS(E_vanilla_agent!$G$2:$G$538,"passed",E_vanilla_agent!$H$2:$H$538,"inapplicable") -> 0 | F27: =COUNTIFS(E_vanilla_agent!$G$2:$G$538,"passed",E_vanilla_agent!$H$2:$H$538,"error") -> 0 | G27: =SUM(C27:F27) -> 180
A28: vanilla_agent | B28: failed | C28: =COUNTIFS(E_vanilla_agent!$G$2:$G$538,"failed",E_vanilla_agent!$H$2:$H$538,"passed") -> 12 | D28: =COUNTIFS(E_vanilla_agent!$G$2:$G$538,"failed",E_vanilla_agent!$H$2:$H$538,"failed") -> 165 | E28: =COUNTIFS(E_vanilla_agent!$G$2:$G$538,"failed",E_vanilla_agent!$H$2:$H$538,"inapplicable") -> 0 | F28: =COUNTIFS(E_vanilla_agent!$G$2:$G$538,"failed",E_vanilla_agent!$H$2:$H$538,"error") -> 0 | G28: =SUM(C28:F28) -> 177
A29: vanilla_agent | B29: inapplicable | C29: =COUNTIFS(E_vanilla_agent!$G$2:$G$538,"inapplicable",E_vanilla_agent!$H$2:$H$538,"passed") -> 42 | D29: =COUNTIFS(E_vanilla_agent!$G$2:$G$538,"inapplicable",E_vanilla_agent!$H$2:$H$538,"failed") -> 72 | E29: =COUNTIFS(E_vanilla_agent!$G$2:$G$538,"inapplicable",E_vanilla_agent!$H$2:$H$538,"inapplicable") -> 66 | F29: =COUNTIFS(E_vanilla_agent!$G$2:$G$538,"inapplicable",E_vanilla_agent!$H$2:$H$538,"error") -> 0 | G29: =SUM(C29:F29) -> 180
A32: Accuracy by persona
A33: Persona | B33: axe | C33: persona_llm | D33: persona_agent | E33: vanilla_llm | F33: vanilla_agent
A34: ade | B34: =IFERROR(COUNTIFS(A_axe!$E$2:$E$538,"ade",A_axe!$I$2:$I$538,1)/COUNTIF(A_axe!$E$2:$E$538,"ade"),"") -> 0.43333333 | C34: =IFERROR(COUNTIFS(B_persona_llm!$E$2:$E$538,"ade",B_persona_llm!$I$2:$I$538,1)/COUNTIF(B_persona_llm!$E$2:$E$538,"ade"),"") -> 0.78888889 | D34: =IFERROR(COUNTIFS(C_persona_agent!$E$2:$E$538,"ade",C_persona_agent!$I$2:$I$538,1)/COUNTIF(C_persona_agent!$E$2:$E$538,"ade"),"") -> 0.53333333 | E34: =IFERROR(COUNTIFS(D_vanilla_llm!$E$2:$E$538,"ade",D_vanilla_llm!$I$2:$I$538,1)/COUNTIF(D_vanilla_llm!$E$2:$E$538,"ade"),"") -> 0.77777778 | F34: =IFERROR(COUNTIFS(E_vanilla_agent!$E$2:$E$538,"ade",E_vanilla_agent!$I$2:$I$538,1)/COUNTIF(E_vanilla_agent!$E$2:$E$538,"ade"),"") -> 0.63333333
A35: elias | B35: =IFERROR(COUNTIFS(A_axe!$E$2:$E$538,"elias",A_axe!$I$2:$I$538,1)/COUNTIF(A_axe!$E$2:$E$538,"elias"),"") -> 0.46666667 | C35: =IFERROR(COUNTIFS(B_persona_llm!$E$2:$E$538,"elias",B_persona_llm!$I$2:$I$538,1)/COUNTIF(B_persona_llm!$E$2:$E$538,"elias"),"") -> 0.84444444 | D35: =IFERROR(COUNTIFS(C_persona_agent!$E$2:$E$538,"elias",C_persona_agent!$I$2:$I$538,1)/COUNTIF(C_persona_agent!$E$2:$E$538,"elias"),"") -> 0.37777778 | E35: =IFERROR(COUNTIFS(D_vanilla_llm!$E$2:$E$538,"elias",D_vanilla_llm!$I$2:$I$538,1)/COUNTIF(D_vanilla_llm!$E$2:$E$538,"elias"),"") -> 0.81111111 | F35: =IFERROR(COUNTIFS(E_vanilla_agent!$E$2:$E$538,"elias",E_vanilla_agent!$I$2:$I$538,1)/COUNTIF(E_vanilla_agent!$E$2:$E$538,"elias"),"") -> 0.33333333
A36: ian | B36: =IFERROR(COUNTIFS(A_axe!$E$2:$E$538,"ian",A_axe!$I$2:$I$538,1)/COUNTIF(A_axe!$E$2:$E$538,"ian"),"") -> 0.43333333 | C36: =IFERROR(COUNTIFS(B_persona_llm!$E$2:$E$538,"ian",B_persona_llm!$I$2:$I$538,1)/COUNTIF(B_persona_llm!$E$2:$E$538,"ian"),"") -> 0.6 | D36: =IFERROR(COUNTIFS(C_persona_agent!$E$2:$E$538,"ian",C_persona_agent!$I$2:$I$538,1)/COUNTIF(C_persona_agent!$E$2:$E$538,"ian"),"") -> 0.5 | E36: =IFERROR(COUNTIFS(D_vanilla_llm!$E$2:$E$538,"ian",D_vanilla_llm!$I$2:$I$538,1)/COUNTIF(D_vanilla_llm!$E$2:$E$538,"ian"),"") -> 0.63333333 | F36: =IFERROR(COUNTIFS(E_vanilla_agent!$E$2:$E$538,"ian",E_vanilla_agent!$I$2:$I$538,1)/COUNTIF(E_vanilla_agent!$E$2:$E$538,"ian"),"") -> 0.6
A37: lakshmi | B37: =IFERROR(COUNTIFS(A_axe!$E$2:$E$538,"lakshmi",A_axe!$I$2:$I$538,1)/COUNTIF(A_axe!$E$2:$E$538,"lakshmi"),"") -> 0.51724138 | C37: =IFERROR(COUNTIFS(B_persona_llm!$E$2:$E$538,"lakshmi",B_persona_llm!$I$2:$I$538,1)/COUNTIF(B_persona_llm!$E$2:$E$538,"lakshmi"),"") -> 0.73563218 | D37: =IFERROR(COUNTIFS(C_persona_agent!$E$2:$E$538,"lakshmi",C_persona_agent!$I$2:$I$538,1)/COUNTIF(C_persona_agent!$E$2:$E$538,"lakshmi"),"") -> 0.66666667 | E37: =IFERROR(COUNTIFS(D_vanilla_llm!$E$2:$E$538,"lakshmi",D_vanilla_llm!$I$2:$I$538,1)/COUNTIF(D_vanilla_llm!$E$2:$E$538,"lakshmi"),"") -> 0.63218391 | F37: =IFERROR(COUNTIFS(E_vanilla_agent!$E$2:$E$538,"lakshmi",E_vanilla_agent!$I$2:$I$538,1)/COUNTIF(E_vanilla_agent!$E$2:$E$538,"lakshmi"),"") -> 0.66666667
A38: sophie | B38: =IFERROR(COUNTIFS(A_axe!$E$2:$E$538,"sophie",A_axe!$I$2:$I$538,1)/COUNTIF(A_axe!$E$2:$E$538,"sophie"),"") -> 0.4 | C38: =IFERROR(COUNTIFS(B_persona_llm!$E$2:$E$538,"sophie",B_persona_llm!$I$2:$I$538,1)/COUNTIF(B_persona_llm!$E$2:$E$538,"sophie"),"") -> 0.66666667 | D38: =IFERROR(COUNTIFS(C_persona_agent!$E$2:$E$538,"sophie",C_persona_agent!$I$2:$I$538,1)/COUNTIF(C_persona_agent!$E$2:$E$538,"sophie"),"") -> 0.45555556 | E38: =IFERROR(COUNTIFS(D_vanilla_llm!$E$2:$E$538,"sophie",D_vanilla_llm!$I$2:$I$538,1)/COUNTIF(D_vanilla_llm!$E$2:$E$538,"sophie"),"") -> 0.71111111 | F38: =IFERROR(COUNTIFS(E_vanilla_agent!$E$2:$E$538,"sophie",E_vanilla_agent!$I$2:$I$538,1)/COUNTIF(E_vanilla_agent!$E$2:$E$538,"sophie"),"") -> 0.54444444
A39: stefan | B39: =IFERROR(COUNTIFS(A_axe!$E$2:$E$538,"stefan",A_axe!$I$2:$I$538,1)/COUNTIF(A_axe!$E$2:$E$538,"stefan"),"") -> 0.4 | C39: =IFERROR(COUNTIFS(B_persona_llm!$E$2:$E$538,"stefan",B_persona_llm!$I$2:$I$538,1)/COUNTIF(B_persona_llm!$E$2:$E$538,"stefan"),"") -> 0.62222222 | D39: =IFERROR(COUNTIFS(C_persona_agent!$E$2:$E$538,"stefan",C_persona_agent!$I$2:$I$538,1)/COUNTIF(C_persona_agent!$E$2:$E$538,"stefan"),"") -> 0.64444444 | E39: =IFERROR(COUNTIFS(D_vanilla_llm!$E$2:$E$538,"stefan",D_vanilla_llm!$I$2:$I$538,1)/COUNTIF(D_vanilla_llm!$E$2:$E$538,"stefan"),"") -> 0.56666667 | F39: =IFERROR(COUNTIFS(E_vanilla_agent!$E$2:$E$538,"stefan",E_vanilla_agent!$I$2:$I$538,1)/COUNTIF(E_vanilla_agent!$E$2:$E$538,"stefan"),"") -> 0.6
A42: Accuracy by WCAG criterion
A43: WCAG criterion | B43: Records (per condition) | C43: axe | D43: persona_llm | E43: persona_agent | F43: vanilla_llm | G43: vanilla_agent
A44: 1.1.1 | B44: =COUNTIF(A_axe!$F$2:$F$538,"1.1.1") -> 18 | C44: =IFERROR(COUNTIFS(A_axe!$F$2:$F$538,"1.1.1",A_axe!$I$2:$I$538,1)/COUNTIF(A_axe!$F$2:$F$538,"1.1.1"),"") -> 0.66666667 | D44: =IFERROR(COUNTIFS(B_persona_llm!$F$2:$F$538,"1.1.1",B_persona_llm!$I$2:$I$538,1)/COUNTIF(B_persona_llm!$F$2:$F$538,"1.1.1"),"") -> 0.83333333 | E44: =IFERROR(COUNTIFS(C_persona_agent!$F$2:$F$538,"1.1.1",C_persona_agent!$I$2:$I$538,1)/COUNTIF(C_persona_agent!$F$2:$F$538,"1.1.1"),"") -> 0.66666667 | F44: =IFERROR(COUNTIFS(D_vanilla_llm!$F$2:$F$538,"1.1.1",D_vanilla_llm!$I$2:$I$538,1)/COUNTIF(D_vanilla_llm!$F$2:$F$538,"1.1.1"),"") -> 0.83333333 | G44: =IFERROR(COUNTIFS(E_vanilla_agent!$F$2:$F$538,"1.1.1",E_vanilla_agent!$I$2:$I$538,1)/COUNTIF(E_vanilla_agent!$F$2:$F$538,"1.1.1"),"") -> 0.72222222
A45: 1.3.1 | B45: =COUNTIF(A_axe!$F$2:$F$538,"1.3.1") -> 36 | C45: =IFERROR(COUNTIFS(A_axe!$F$2:$F$538,"1.3.1",A_axe!$I$2:$I$538,1)/COUNTIF(A_axe!$F$2:$F$538,"1.3.1"),"") -> 0.66666667 | D45: =IFERROR(COUNTIFS(B_persona_llm!$F$2:$F$538,"1.3.1",B_persona_llm!$I$2:$I$538,1)/COUNTIF(B_persona_llm!$F$2:$F$538,"1.3.1"),"") -> 0.83333333 | E45: =IFERROR(COUNTIFS(C_persona_agent!$F$2:$F$538,"1.3.1",C_persona_agent!$I$2:$I$538,1)/COUNTIF(C_persona_agent!$F$2:$F$538,"1.3.1"),"") -> 0.75 | F45: =IFERROR(COUNTIFS(D_vanilla_llm!$F$2:$F$538,"1.3.1",D_vanilla_llm!$I$2:$I$538,1)/COUNTIF(D_vanilla_llm!$F$2:$F$538,"1.3.1"),"") -> 0.69444444 | G45: =IFERROR(COUNTIFS(E_vanilla_agent!$F$2:$F$538,"1.3.1",E_vanilla_agent!$I$2:$I$538,1)/COUNTIF(E_vanilla_agent!$F$2:$F$538,"1.3.1"),"") -> 0.97222222
A46: 1.3.5 | B46: =COUNTIF(A_axe!$F$2:$F$538,"1.3.5") -> 18 | C46: =IFERROR(COUNTIFS(A_axe!$F$2:$F$538,"1.3.5",A_axe!$I$2:$I$538,1)/COUNTIF(A_axe!$F$2:$F$538,"1.3.5"),"") -> 0.66666667 | D46: =IFERROR(COUNTIFS(B_persona_llm!$F$2:$F$538,"1.3.5",B_persona_llm!$I$2:$I$538,1)/COUNTIF(B_persona_llm!$F$2:$F$538,"1.3.5"),"") -> 1 | E46: =IFERROR(COUNTIFS(C_persona_agent!$F$2:$F$538,"1.3.5",C_persona_agent!$I$2:$I$538,1)/COUNTIF(C_persona_agent!$F$2:$F$538,"1.3.5"),"") -> 0.38888889 | F46: =IFERROR(COUNTIFS(D_vanilla_llm!$F$2:$F$538,"1.3.5",D_vanilla_llm!$I$2:$I$538,1)/COUNTIF(D_vanilla_llm!$F$2:$F$538,"1.3.5"),"") -> 0.83333333 | G46: =IFERROR(COUNTIFS(E_vanilla_agent!$F$2:$F$538,"1.3.5",E_vanilla_agent!$I$2:$I$538,1)/COUNTIF(E_vanilla_agent!$F$2:$F$538,"1.3.5"),"") -> 0.33333333
A47: 1.4.3 | B47: =COUNTIF(A_axe!$F$2:$F$538,"1.4.3") -> 18 | C47: =IFERROR(COUNTIFS(A_axe!$F$2:$F$538,"1.4.3",A_axe!$I$2:$I$538,1)/COUNTIF(A_axe!$F$2:$F$538,"1.4.3"),"") -> 0.33333333 | D47: =IFERROR(COUNTIFS(B_persona_llm!$F$2:$F$538,"1.4.3",B_persona_llm!$I$2:$I$538,1)/COUNTIF(B_persona_llm!$F$2:$F$538,"1.4.3"),"") -> 0.83333333 | E47: =IFERROR(COUNTIFS(C_persona_agent!$F$2:$F$538,"1.4.3",C_persona_agent!$I$2:$I$538,1)/COUNTIF(C_persona_agent!$F$2:$F$538,"1.4.3"),"") -> 0.44444444 | F47: =IFERROR(COUNTIFS(D_vanilla_llm!$F$2:$F$538,"1.4.3",D_vanilla_llm!$I$2:$I$538,1)/COUNTIF(D_vanilla_llm!$F$2:$F$538,"1.4.3"),"") -> 0.83333333 | G47: =IFERROR(COUNTIFS(E_vanilla_agent!$F$2:$F$538,"1.4.3",E_vanilla_agent!$I$2:$I$538,1)/COUNTIF(E_vanilla_agent!$F$2:$F$538,"1.4.3"),"") -> 0.33333333
A48: 1.4.12 | B48: =COUNTIF(A_axe!$F$2:$F$538,"1.4.12") -> 36 | C48: =IFERROR(COUNTIFS(A_axe!$F$2:$F$538,"1.4.12",A_axe!$I$2:$I$538,1)/COUNTIF(A_axe!$F$2:$F$538,"1.4.12"),"") -> 0.5 | D48: =IFERROR(COUNTIFS(B_persona_llm!$F$2:$F$538,"1.4.12",B_persona_llm!$I$2:$I$538,1)/COUNTIF(B_persona_llm!$F$2:$F$538,"1.4.12"),"") -> 0.83333333 | E48: =IFERROR(COUNTIFS(C_persona_agent!$F$2:$F$538,"1.4.12",C_persona_agent!$I$2:$I$538,1)/COUNTIF(C_persona_agent!$F$2:$F$538,"1.4.12"),"") -> 0.55555556 | F48: =IFERROR(COUNTIFS(D_vanilla_llm!$F$2:$F$538,"1.4.12",D_vanilla_llm!$I$2:$I$538,1)/COUNTIF(D_vanilla_llm!$F$2:$F$538,"1.4.12"),"") -> 0.72222222 | G48: =IFERROR(COUNTIFS(E_vanilla_agent!$F$2:$F$538,"1.4.12",E_vanilla_agent!$I$2:$I$538,1)/COUNTIF(E_vanilla_agent!$F$2:$F$538,"1.4.12"),"") -> 0.66666667
...

Sheet A_axe
A1: snippet_id | B1: condition | C1: condition_key | D1: model | E1: persona | F1: wcag_criterion | G1: expected | H1: evaluated | I1: correct | J1: repetition | K1: severity | L1: issue_count | M1: tool_call_count | N1: tools_called | O1: iteration_count | P1: total_time_seconds | Q1: input_tokens | R1: output_tokens | S1: testcase_title | T1: rule_id | U1: rule_name | V1: corpus_source | W1: rule_url | X1: html_path | Y1: overall_assessment | Z1: issues_detail
A2: 033e04cced5973596d9aa724feacb027d23b4c53 | B2: axe | C2: A | D2: n/a | E2: ade | F2: 2.1.1 | G2: inapplicable | H2: passed | I2: =IF(EXACT(G2,H2),1,0) -> 0 | J2: 0 | K2: N/A | L2: 0 | M2: 1 | N2: axe-core | O2: 1 | P2: 4.7 | S2: Inapplicable Example 2 | T2: akn7bn | U2: Iframe with interactive elements is not excluded from tab-order | W2: https://www.w3.org/WAI/content-assets/wcag-act-rules/testcases/akn7bn/033e04cced5973596d9aa724feacb027d23b4c53.html | X2: corpus1\ade\2.1.1\inapplicable\033e04cced5973596d9aa724feacb027d23b4c53.html | Y2: Found 2 rule violation(s) affecting 2 element(s).
A3: 033e04cced5973596d9aa724feacb027d23b4c53 | B3: axe | C3: A | D3: n/a | E3: ade | F3: 2.1.1 | G3: inapplicable | H3: passed | I3: =IF(EXACT(G3,H3),1,0) -> 0 | J3: 1 | K3: N/A | L3: 0 | M3: 1 | N3: axe-core | O3: 1 | P3: 4.48 | S3: Inapplicable Example 2 | T3: akn7bn | U3: Iframe with interactive elements is not excluded from tab-order | W3: https://www.w3.org/WAI/content-assets/wcag-act-rules/testcases/akn7bn/033e04cced5973596d9aa724feacb027d23b4c53.html | X3: corpus1\ade\2.1.1\inapplicable\033e04cced5973596d9aa724feacb027d23b4c53.html | Y3: Found 2 rule violation(s) affecting 2 element(s).
A4: 033e04cced5973596d9aa724feacb027d23b4c53 | B4: axe | C4: A | D4: n/a | E4: ade | F4: 2.1.1 | G4: inapplicable | H4: passed | I4: =IF(EXACT(G4,H4),1,0) -> 0 | J4: 2 | K4: N/A | L4: 0 | M4: 1 | N4: axe-core | O4: 1 | P4: 5 | S4: Inapplicable Example 2 | T4: akn7bn | U4: Iframe with interactive elements is not excluded from tab-order | W4: https://www.w3.org/WAI/content-assets/wcag-act-rules/testcases/akn7bn/033e04cced5973596d9aa724feacb027d23b4c53.html | X4: corpus1\ade\2.1.1\inapplicable\033e04cced5973596d9aa724feacb027d23b4c53.html | Y4: Found 2 rule violation(s) affecting 2 element(s).
A5: 17a371c470316dc29e424101065ebfe9f7b2e990 | B5: axe | C5: A | D5: n/a | E5: ade | F5: 2.1.1 | G5: inapplicable | H5: passed | I5: =IF(EXACT(G5,H5),1,0) -> 0 | J5: 0 | K5: N/A | L5: 0 | M5: 1 | N5: axe-core | O5: 1 | P5: 4.5 | S5: Inapplicable Example 5 | T5: akn7bn | U5: Iframe with interactive elements is not excluded from tab-order | W5: https://www.w3.org/WAI/content-assets/wcag-act-rules/testcases/akn7bn/17a371c470316dc29e424101065ebfe9f7b2e990.html | X5: corpus1\ade\2.1.1\inapplicable\17a371c470316dc29e424101065ebfe9f7b2e990.html | Y5: Found 2 rule violation(s) affecting 2 element(s).
A6: 17a371c470316dc29e424101065ebfe9f7b2e990 | B6: axe | C6: A | D6: n/a | E6: ade | F6: 2.1.1 | G6: inapplicable | H6: passed | I6: =IF(EXACT(G6,H6),1,0) -> 0 | J6: 1 | K6: N/A | L6: 0 | M6: 1 | N6: axe-core | O6: 1 | P6: 4.53 | S6: Inapplicable Example 5 | T6: akn7bn | U6: Iframe with interactive elements is not excluded from tab-order | W6: https://www.w3.org/WAI/content-assets/wcag-act-rules/testcases/akn7bn/17a371c470316dc29e424101065ebfe9f7b2e990.html | X6: corpus1\ade\2.1.1\inapplicable\17a371c470316dc29e424101065ebfe9f7b2e990.html | Y6: Found 2 rule violation(s) affecting 2 element(s).
A7: 17a371c470316dc29e424101065ebfe9f7b2e990 | B7: axe | C7: A | D7: n/a | E7: ade | F7: 2.1.1 | G7: inapplicable | H7: passed | I7: =IF(EXACT(G7,H7),1,0) -> 0 | J7: 2 | K7: N/A | L7: 0 | M7: 1 | N7: axe-core | O7: 1 | P7: 3.53 | S7: Inapplicable Example 5 | T7: akn7bn | U7: Iframe with interactive elements is not excluded from tab-order | W7: https://www.w3.org/WAI/content-assets/wcag-act-rules/testcases/akn7bn/17a371c470316dc29e424101065ebfe9f7b2e990.html | X7: corpus1\ade\2.1.1\inapplicable\17a371c470316dc29e424101065ebfe9f7b2e990.html | Y7: Found 2 rule violation(s) affecting 2 element(s).
A8: 1e3939d9f8e0f78f9c564ec6feb12cc5635c0acb | B8: axe | C8: A | D8: n/a | E8: ade | F8: 2.1.1 | G8: passed | H8: passed | I8: =IF(EXACT(G8,H8),1,0) -> 1 | J8: 0 | K8: N/A | L8: 0 | M8: 1 | N8: axe-core | O8: 1 | P8: 5.64 | S8: Passed Example 1 | T8: akn7bn | U8: Iframe with interactive elements is not excluded from tab-order | W8: https://www.w3.org/WAI/content-assets/wcag-act-rules/testcases/akn7bn/1e3939d9f8e0f78f9c564ec6feb12cc5635c0acb.html | X8: corpus1\ade\2.1.1\passed\1e3939d9f8e0f78f9c564ec6feb12cc5635c0acb.html | Y8: Found 3 rule violation(s) affecting 3 element(s).
A9: 1e3939d9f8e0f78f9c564ec6feb12cc5635c0acb | B9: axe | C9: A | D9: n/a | E9: ade | F9: 2.1.1 | G9: passed | H9: passed | I9: =IF(EXACT(G9,H9),1,0) -> 1 | J9: 1 | K9: N/A | L9: 0 | M9: 1 | N9: axe-core | O9: 1 | P9: 4.67 | S9: Passed Example 1 | T9: akn7bn | U9: Iframe with interactive elements is not excluded from tab-order | W9: https://www.w3.org/WAI/content-assets/wcag-act-rules/testcases/akn7bn/1e3939d9f8e0f78f9c564ec6feb12cc5635c0acb.html | X9: corpus1\ade\2.1.1\passed\1e3939d9f8e0f78f9c564ec6feb12cc5635c0acb.html | Y9: Found 3 rule violation(s) affecting 3 element(s).
A10: 1e3939d9f8e0f78f9c564ec6feb12cc5635c0acb | B10: axe | C10: A | D10: n/a | E10: ade | F10: 2.1.1 | G10: passed | H10: passed | I10: =IF(EXACT(G10,H10),1,0) -> 1 | J10: 2 | K10: N/A | L10: 0 | M10: 1 | N10: axe-core | O10: 1 | P10: 4.45 | S10: Passed Example 1 | T10: akn7bn | U10: Iframe with interactive elements is not excluded from tab-order | W10: https://www.w3.org/WAI/content-assets/wcag-act-rules/testcases/akn7bn/1e3939d9f8e0f78f9c564ec6feb12cc5635c0acb.html | X10: corpus1\ade\2.1.1\passed\1e3939d9f8e0f78f9c564ec6feb12cc5635c0acb.html | Y10: Found 3 rule violation(s) affecting 3 element(s).
A11: 270a22a8e4ce4d9f073e1484a0d807705207a1d7 | B11: axe | C11: A | D11: n/a | E11: ade | F11: 2.1.1 | G11: passed | H11: passed | I11: =IF(EXACT(G11,H11),1,0) -> 1 | J11: 0 | K11: N/A | L11: 0 | M11: 1 | N11: axe-core | O11: 1 | P11: 4.24 | S11: Passed Example 2 | T11: 0ssw9k | U11: Scrollable content can be reached with sequential focus navigation | W11: https://www.w3.org/WAI/content-assets/wcag-act-rules/testcases/0ssw9k/270a22a8e4ce4d9f073e1484a0d807705207a1d7.html | X11: corpus1\ade\2.1.1\passed\270a22a8e4ce4d9f073e1484a0d807705207a1d7.html | Y11: Found 2 rule violation(s) affecting 2 element(s).
A12: 270a22a8e4ce4d9f073e1484a0d807705207a1d7 | B12: axe | C12: A | D12: n/a | E12: ade | F12: 2.1.1 | G12: passed | H12: passed | I12: =IF(EXACT(G12,H12),1,0) -> 1 | J12: 1 | K12: N/A | L12: 0 | M12: 1 | N12: axe-core | O12: 1 | P12: 4.17 | S12: Passed Example 2 | T12: 0ssw9k | U12: Scrollable content can be reached with sequential focus navigation | W12: https://www.w3.org/WAI/content-assets/wcag-act-rules/testcases/0ssw9k/270a22a8e4ce4d9f073e1484a0d807705207a1d7.html | X12: corpus1\ade\2.1.1\passed\270a22a8e4ce4d9f073e1484a0d807705207a1d7.html | Y12: Found 2 rule violation(s) affecting 2 element(s).
A13: 270a22a8e4ce4d9f073e1484a0d807705207a1d7 | B13: axe | C13: A | D13: n/a | E13: ade | F13: 2.1.1 | G13: passed | H13: passed | I13: =IF(EXACT(G13,H13),1,0) -> 1 | J13: 2 | K13: N/A | L13: 0 | M13: 1 | N13: axe-core | O13: 1 | P13: 4.12 | S13: Passed Example 2 | T13: 0ssw9k | U13: Scrollable content can be reached with sequential focus navigation | W13: https://www.w3.org/WAI/content-assets/wcag-act-rules/testcases/0ssw9k/270a22a8e4ce4d9f073e1484a0d807705207a1d7.html | X13: corpus1\ade\2.1.1\passed\270a22a8e4ce4d9f073e1484a0d807705207a1d7.html | Y13: Found 2 rule violation(s) affecting 2 element(s).
A14: 5fa34d0a7eea03109cd12c0e7c21fce793c268db | B14: axe | C14: A | D14: n/a | E14: ade | F14: 2.1.1 | G14: failed | H14: failed | I14: =IF(EXACT(G14,H14),1,0) -> 1 | J14: 0 | K14: serious | L14: 1 | M14: 1 | N14: axe-core | O14: 1 | P14: 4.66 | S14: Failed Example 1 | T14: 0ssw9k | U14: Scrollable content can be reached with sequential focus navigation | W14: https://www.w3.org/WAI/content-assets/wcag-act-rules/testcases/0ssw9k/5fa34d0a7eea03109cd12c0e7c21fce793c268db.html | X14: corpus1\ade\2.1.1\failed\5fa34d0a7eea03109cd12c0e7c21fce793c268db.html | Y14: Found 3 rule violation(s) affecting 3 element(s). | Z14: [wcag2a, wcag211] Ensure elements that have scrollable content are accessible by keyboard Scrollable region must have keyboard access
A15: 5fa34d0a7eea03109cd12c0e7c21fce793c268db | B15: axe | C15: A | D15: n/a | E15: ade | F15: 2.1.1 | G15: failed | H15: failed | I15: =IF(EXACT(G15,H15),1,0) -> 1 | J15: 1 | K15: serious | L15: 1 | M15: 1 | N15: axe-core | O15: 1 | P15: 4.16 | S15: Failed Example 1 | T15: 0ssw9k | U15: Scrollable content can be reached with sequential focus navigation | W15: https://www.w3.org/WAI/content-assets/wcag-act-rules/testcases/0ssw9k/5fa34d0a7eea03109cd12c0e7c21fce793c268db.html | X15: corpus1\ade\2.1.1\failed\5fa34d0a7eea03109cd12c0e7c21fce793c268db.html | Y15: Found 3 rule violation(s) affecting 3 element(s). | Z15: [wcag2a, wcag211] Ensure elements that have scrollable content are accessible by keyboard Scrollable region must have keyboard access
A16: 5fa34d0a7eea03109cd12c0e7c21fce793c268db | B16: axe | C16: A | D16: n/a | E16: ade | F16: 2.1.1 | G16: failed | H16: failed | I16: =IF(EXACT(G16,H16),1,0) -> 1 | J16: 2 | K16: serious | L16: 1 | M16: 1 | N16: axe-core | O16: 1 | P16: 4.15 | S16: Failed Example 1 | T16: 0ssw9k | U16: Scrollable content can be reached with sequential focus navigation | W16: https://www.w3.org/WAI/content-assets/wcag-act-rules/testcases/0ssw9k/5fa34d0a7eea03109cd12c0e7c21fce793c268db.html | X16: corpus1\ade\2.1.1\failed\5fa34d0a7eea03109cd12c0e7c21fce793c268db.html | Y16: Found 3 rule violation(s) affecting 3 element(s). | Z16: [wcag2a, wcag211] Ensure elements that have scrollable content are accessible by keyboard Scrollable region must have keyboard access
A17: 62673162e22ee1e95e962522b1d1c3b549dbfc49 | B17: axe | C17: A | D17: n/a | E17: ade | F17: 2.1.1 | G17: failed | H17: passed | I17: =IF(EXACT(G17,H17),1,0) -> 0 | J17: 0 | K17: N/A | L17: 0 | M17: 1 | N17: axe-core | O17: 1 | P17: 5.24 | S17: Failed Example 1 | T17: akn7bn | U17: Iframe with interactive elements is not excluded from tab-order | W17: https://www.w3.org/WAI/content-assets/wcag-act-rules/testcases/akn7bn/62673162e22ee1e95e962522b1d1c3b549dbfc49.html | X17: corpus1\ade\2.1.1\failed\62673162e22ee1e95e962522b1d1c3b549dbfc49.html | Y17: Found 2 rule violation(s) affecting 2 element(s).
A18: 62673162e22ee1e95e962522b1d1c3b549dbfc49 | B18: axe | C18: A | D18: n/a | E18: ade | F18: 2.1.1 | G18: failed | H18: passed | I18: =IF(EXACT(G18,H18),1,0) -> 0 | J18: 1 | K18: N/A | L18: 0 | M18: 1 | N18: axe-core | O18: 1 | P18: 5.33 | S18: Failed Example 1 | T18: akn7bn | U18: Iframe with interactive elements is not excluded from tab-order | W18: https://www.w3.org/WAI/content-assets/wcag-act-rules/testcases/akn7bn/62673162e22ee1e95e962522b1d1c3b549dbfc49.html | X18: corpus1\ade\2.1.1\failed\62673162e22ee1e95e962522b1d1c3b549dbfc49.html | Y18: Found 2 rule violation(s) affecting 2 element(s).
A19: 62673162e22ee1e95e962522b1d1c3b549dbfc49 | B19: axe | C19: A | D19: n/a | E19: ade | F19: 2.1.1 | G19: failed | H19: passed | I19: =IF(EXACT(G19,H19),1,0) -> 0 | J19: 2 | K19: N/A | L19: 0 | M19: 1 | N19: axe-core | O19: 1 | P19: 5.2 | S19: Failed Example 1 | T19: akn7bn | U19: Iframe with interactive elements is not excluded from tab-order | W19: https://www.w3.org/WAI/content-assets/wcag-act-rules/testcases/akn7bn/62673162e22ee1e95e962522b1d1c3b549dbfc49.html | X19: corpus1\ade\2.1.1\failed\62673162e22ee1e95e962522b1d1c3b549dbfc49.html | Y19: Found 2 rule violation(s) affecting 2 element(s).
A20: 0bf30cdf02ff26dfca5aa705b7023227da221e05 | B20: axe | C20: A | D20: n/a | E20: ade | F20: 2.2.1 | G20: inapplicable | H20: passed | I20: =IF(EXACT(G20,H20),1,0) -> 0 | J20: 0 | K20: N/A | L20: 0 | M20: 1 | N20: axe-core | O20: 1 | P20: 4.62 | S20: Inapplicable Example 7 | T20: bc659a | U20: Meta element has no refresh delay | W20: https://www.w3.org/WAI/content-assets/wcag-act-rules/testcases/bc659a/0bf30cdf02ff26dfca5aa705b7023227da221e05.html | X20: corpus1\ade\2.2.1\inapplicable\0bf30cdf02ff26dfca5aa705b7023227da221e05.html | Y20: Found 4 rule violation(s) affecting 4 element(s).
A21: 0bf30cdf02ff26dfca5aa705b7023227da221e05 | B21: axe | C21: A | D21: n/a | E21: ade | F21: 2.2.1 | G21: inapplicable | H21: passed | I21: =IF(EXACT(G21,H21),1,0) -> 0 | J21: 1 | K21: N/A | L21: 0 | M21: 1 | N21: axe-core | O21: 1 | P21: 4.54 | S21: Inapplicable Example 7 | T21: bc659a | U21: Meta element has no refresh delay | W21: https://www.w3.org/WAI/content-assets/wcag-act-rules/testcases/bc659a/0bf30cdf02ff26dfca5aa705b7023227da221e05.html | X21: corpus1\ade\2.2.1\inapplicable\0bf30cdf02ff26dfca5aa705b7023227da221e05.html | Y21: Found 4 rule violation(s) affecting 4 element(s).
A22: 0bf30cdf02ff26dfca5aa705b7023227da221e05 | B22: axe | C22: A | D22: n/a | E22: ade | F22: 2.2.1 | G22: inapplicable | H22: passed | I22: =IF(EXACT(G22,H22),1,0) -> 0 | J22: 2 | K22: N/A | L22: 0 | M22: 1 | N22: axe-core | O22: 1 | P22: 4.31 | S22: Inapplicable Example 7 | T22: bc659a | U22: Meta element has no refresh delay | W22: https://www.w3.org/WAI/content-assets/wcag-act-rules/testcases/bc659a/0bf30cdf02ff26dfca5aa705b7023227da221e05.html | X22: corpus1\ade\2.2.1\inapplicable\0bf30cdf02ff26dfca5aa705b7023227da221e05.html | Y22: Found 4 rule violation(s) affecting 4 element(s).
A23: 48a600254c0883cd5a72471420b1ac5a532ca6c3 | B23: axe | C23: A | D23: n/a | E23: ade | F23: 2.2.1 | G23: inapplicable | H23: passed | I23: =IF(EXACT(G23,H23),1,0) -> 0 | J23: 0 | K23: N/A | L23: 0 | M23: 1 | N23: axe-core | O23: 1 | P23: 4.61 | S23: Inapplicable Example 1 | T23: bc659a | U23: Meta element has no refresh delay | W23: https://www.w3.org/WAI/content-assets/wcag-act-rules/testcases/bc659a/48a600254c0883cd5a72471420b1ac5a532ca6c3.html | X23: corpus1\ade\2.2.1\inapplicable\48a600254c0883cd5a72471420b1ac5a532ca6c3.html | Y23: Found 4 rule violation(s) affecting 4 element(s).
A24: 48a600254c0883cd5a72471420b1ac5a532ca6c3 | B24: axe | C24: A | D24: n/a | E24: ade | F24: 2.2.1 | G24: inapplicable | H24: passed | I24: =IF(EXACT(G24,H24),1,0) -> 0 | J24: 1 | K24: N/A | L24: 0 | M24: 1 | N24: axe-core | O24: 1 | P24: 4.87 | S24: Inapplicable Example 1 | T24: bc659a | U24: Meta element has no refresh delay | W24: https://www.w3.org/WAI/content-assets/wcag-act-rules/testcases/bc659a/48a600254c0883cd5a72471420b1ac5a532ca6c3.html | X24: corpus1\ade\2.2.1\inapplicable\48a600254c0883cd5a72471420b1ac5a532ca6c3.html | Y24: Found 4 rule violation(s) affecting 4 element(s).
A25: 48a600254c0883cd5a72471420b1ac5a532ca6c3 | B25: axe | C25: A | D25: n/a | E25: ade | F25: 2.2.1 | G25: inapplicable | H25: passed | I25: =IF(EXACT(G25,H25),1,0) -> 0 | J25: 2 | K25: N/A | L25: 0 | M25: 1 | N25: axe-core | O25: 1 | P25: 4.78 | S25: Inapplicable Example 1 | T25: bc659a | U25: Meta element has no refresh delay | W25: https://www.w3.org/WAI/content-assets/wcag-act-rules/testcases/bc659a/48a600254c0883cd5a72471420b1ac5a532ca6c3.html | X25: corpus1\ade\2.2.1\inapplicable\48a600254c0883cd5a72471420b1ac5a532ca6c3.html | Y25: Found 4 rule violation(s) affecting 4 element(s).
A26: 49d79a4e4e4a994a8eb7cf2eaf59c99d2251cac5 | B26: axe | C26: A | D26: n/a | E26: ade | F26: 2.2.1 | G26: passed | H26: passed | I26: =IF(EXACT(G26,H26),1,0) -> 1 | J26: 0 | K26: N/A | L26: 0 | M26: 1 | N26: axe-core | O26: 1 | P26: 5.81 | S26: Passed Example 1 | T26: bc659a | U26: Meta element has no refresh delay | W26: https://www.w3.org/WAI/content-assets/wcag-act-rules/testcases/bc659a/49d79a4e4e4a994a8eb7cf2eaf59c99d2251cac5.html | X26: corpus1\ade\2.2.1\passed\49d79a4e4e4a994a8eb7cf2eaf59c99d2251cac5.html | Y26: Found 1 rule violation(s) affecting 1 element(s).
A27: 49d79a4e4e4a994a8eb7cf2eaf59c99d2251cac5 | B27: axe | C27: A | D27: n/a | E27: ade | F27: 2.2.1 | G27: passed | H27: passed | I27: =IF(EXACT(G27,H27),1,0) -> 1 | J27: 1 | K27: N/A | L27: 0 | M27: 1 | N27: axe-core | O27: 1 | P27: 5.82 | S27: Passed Example 1 | T27: bc659a | U27: Meta element has no refresh delay | W27: https://www.w3.org/WAI/content-assets/wcag-act-rules/testcases/bc659a/49d79a4e4e4a994a8eb7cf2eaf59c99d2251cac5.html | X27: corpus1\ade\2.2.1\passed\49d79a4e4e4a994a8eb7cf2eaf59c99d2251cac5.html | Y27: Found 1 rule violation(s) affecting 1 element(s).
A28: 49d79a4e4e4a994a8eb7cf2eaf59c99d2251cac5 | B28: axe | C28: A | D28: n/a | E28: ade | F28: 2.2.1 | G28: passed | H28: passed | I28: =IF(EXACT(G28,H28),1,0) -> 1 | J28: 2 | K28: N/A | L28: 0 | M28: 1 | N28: axe-core | O28: 1 | P28: 6.12 | S28: Passed Example 1 | T28: bc659a | U28: Meta element has no refresh delay | W28: https://www.w3.org/WAI/content-assets/wcag-act-rules/testcases/bc659a/49d79a4e4e4a994a8eb7cf2eaf59c99d2251cac5.html | X28: corpus1\ade\2.2.1\passed\49d79a4e4e4a994a8eb7cf2eaf59c99d2251cac5.html | Y28: Found 1 rule violation(s) affecting 1 element(s).
A29: 56857820788db21498e95a5cbba65d59a9a2b892 | B29: axe | C29: A | D29: n/a | E29: ade | F29: 2.2.1 | G29: failed | H29: failed | I29: =IF(EXACT(G29,H29),1,0) -> 1 | J29: 0 | K29: critical | L29: 1 | M29: 1 | N29: axe-core | O29: 1 | P29: 3.51 | S29: Failed Example 1 | T29: bc659a | U29: Meta element has no refresh delay | W29: https://www.w3.org/WAI/content-assets/wcag-act-rules/testcases/bc659a/56857820788db21498e95a5cbba65d59a9a2b892.html | X29: corpus1\ade\2.2.1\failed\56857820788db21498e95a5cbba65d59a9a2b892.html | Y29: Found 5 rule violation(s) affecting 5 element(s). | Z29: [wcag2a, wcag221] Ensures <meta http-equiv="refresh"> is not used for delayed refresh Delayed refresh under 20 hours must not be used
A30: 56857820788db21498e95a5cbba65d59a9a2b892 | B30: axe | C30: A | D30: n/a | E30: ade | F30: 2.2.1 | G30: failed | H30: failed | I30: =IF(EXACT(G30,H30),1,0) -> 1 | J30: 1 | K30: critical | L30: 1 | M30: 1 | N30: axe-core | O30: 1 | P30: 3.51 | S30: Failed Example 1 | T30: bc659a | U30: Meta element has no refresh delay | W30: https://www.w3.org/WAI/content-assets/wcag-act-rules/testcases/bc659a/56857820788db21498e95a5cbba65d59a9a2b892.html | X30: corpus1\ade\2.2.1\failed\56857820788db21498e95a5cbba65d59a9a2b892.html | Y30: Found 5 rule violation(s) affecting 5 element(s). | Z30: [wcag2a, wcag221] Ensures <meta http-equiv="refresh"> is not used for delayed refresh Delayed refresh under 20 hours must not be used
A31: 56857820788db21498e95a5cbba65d59a9a2b892 | B31: axe | C31: A | D31: n/a | E31: ade | F31: 2.2.1 | G31: failed | H31: failed | I31: =IF(EXACT(G31,H31),1,0) -> 1 | J31: 2 | K31: critical | L31: 1 | M31: 1 | N31: axe-core | O31: 1 | P31: 3.51 | S31: Failed Example 1 | T31: bc659a | U31: Meta element has no refresh delay | W31: https://www.w3.org/WAI/content-assets/wcag-act-rules/testcases/bc659a/56857820788db21498e95a5cbba65d59a9a2b892.html | X31: corpus1\ade\2.2.1\failed\56857820788db21498e95a5cbba65d59a9a2b892.html | Y31: Found 5 rule violation(s) affecting 5 element(s). | Z31: [wcag2a, wcag221] Ensures <meta http-equiv="refresh"> is not used for delayed refresh Delayed refresh under 20 hours must not be used
A32: 5d4d5b214459c8a0779600ab39a5668003271c62 | B32: axe | C32: A | D32: n/a | E32: ade | F32: 2.2.1 | G32: failed | H32: failed | I32: =IF(EXACT(G32,H32),1,0) -> 1 | J32: 0 | K32: critical | L32: 1 | M32: 1 | N32: axe-core | O32: 1 | P32: 3.51 | S32: Failed Example 4 | T32: bc659a | U32: Meta element has no refresh delay | W32: https://www.w3.org/WAI/content-assets/wcag-act-rules/testcases/bc659a/5d4d5b214459c8a0779600ab39a5668003271c62.html | X32: corpus1\ade\2.2.1\failed\5d4d5b214459c8a0779600ab39a5668003271c62.html | Y32: Found 5 rule violation(s) affecting 5 element(s). | Z32: [wcag2a, wcag221] Ensures <meta http-equiv="refresh"> is not used for delayed refresh Delayed refresh under 20 hours must not be used
A33: 5d4d5b214459c8a0779600ab39a5668003271c62 | B33: axe | C33: A | D33: n/a | E33: ade | F33: 2.2.1 | G33: failed | H33: failed | I33: =IF(EXACT(G33,H33),1,0) -> 1 | J33: 1 | K33: critical | L33: 1 | M33: 1 | N33: axe-core | O33: 1 | P33: 3.51 | S33: Failed Example 4 | T33: bc659a | U33: Meta element has no refresh delay | W33: https://www.w3.org/WAI/content-assets/wcag-act-rules/testcases/bc659a/5d4d5b214459c8a0779600ab39a5668003271c62.html | X33: corpus1\ade\2.2.1\failed\5d4d5b214459c8a0779600ab39a5668003271c62.html | Y33: Found 5 rule violation(s) affecting 5 element(s). | Z33: [wcag2a, wcag221] Ensures <meta http-equiv="refresh"> is not used for delayed refresh Delayed refresh under 20 hours must not be used
A34: 5d4d5b214459c8a0779600ab39a5668003271c62 | B34: axe | C34: A | D34: n/a | E34: ade | F34: 2.2.1 | G34: failed | H34: failed | I34: =IF(EXACT(G34,H34),1,0) -> 1 | J34: 2 | K34: critical | L34: 1 | M34: 1 | N34: axe-core | O34: 1 | P34: 3.51 | S34: Failed Example 4 | T34: bc659a | U34: Meta element has no refresh delay | W34: https://www.w3.org/WAI/content-assets/wcag-act-rules/testcases/bc659a/5d4d5b214459c8a0779600ab39a5668003271c62.html | X34: corpus1\ade\2.2.1\failed\5d4d5b214459c8a0779600ab39a5668003271c62.html | Y34: Found 5 rule violation(s) affecting 5 element(s). | Z34: [wcag2a, wcag221] Ensures <meta http-equiv="refresh"> is not used for delayed refresh Delayed refresh under 20 hours must not be used
A35: b5ca868de7980f6944142ecdb849f47ad2cdfb5c | B35: axe | C35: A | D35: n/a | E35: ade | F35: 2.2.1 | G35: passed | H35: passed | I35: =IF(EXACT(G35,H35),1,0) -> 1 | J35: 0 | K35: N/A | L35: 0 | M35: 1 | N35: axe-core | O35: 1 | P35: 3.6 | S35: Passed Example 3 | T35: bc659a | U35: Meta element has no refresh delay | W35: https://www.w3.org/WAI/content-assets/wcag-act-rules/testcases/bc659a/b5ca868de7980f6944142ecdb849f47ad2cdfb5c.html | X35: corpus1\ade\2.2.1\passed\b5ca868de7980f6944142ecdb849f47ad2cdfb5c.html | Y35: Found 3 rule violation(s) affecting 3 element(s).
A36: b5ca868de7980f6944142ecdb849f47ad2cdfb5c | B36: axe | C36: A | D36: n/a | E36: ade | F36: 2.2.1 | G36: passed | H36: passed | I36: =IF(EXACT(G36,H36),1,0) -> 1 | J36: 1 | K36: N/A | L36: 0 | M36: 1 | N36: axe-core | O36: 1 | P36: 3.53 | S36: Passed Example 3 | T36: bc659a | U36: Meta element has no refresh delay | W36: https://www.w3.org/WAI/content-assets/wcag-act-rules/testcases/bc659a/b5ca868de7980f6944142ecdb849f47ad2cdfb5c.html | X36: corpus1\ade\2.2.1\passed\b5ca868de7980f6944142ecdb849f47ad2cdfb5c.html | Y36: Found 3 rule violation(s) affecting 3 element(s).
A37: b5ca868de7980f6944142ecdb849f47ad2cdfb5c | B37: axe | C37: A | D37: n/a | E37: ade | F37: 2.2.1 | G37: passed | H37: passed | I37: =IF(EXACT(G37,H37),1,0) -> 1 | J37: 2 | K37: N/A | L37: 0 | M37: 1 | N37: axe-core | O37: 1 | P37: 3.57 | S37: Passed Example 3 | T37: bc659a | U37: Meta element has no refresh delay | W37: https://www.w3.org/WAI/content-assets/wcag-act-rules/testcases/bc659a/b5ca868de7980f6944142ecdb849f47ad2cdfb5c.html | X37: corpus1\ade\2.2.1\passed\b5ca868de7980f6944142ecdb849f47ad2cdfb5c.html | Y37: Found 3 rule violation(s) affecting 3 element(s).
A38: ha-2-4-3-fail-01-positive-tabindex | B38: axe | C38: A | D38: n/a | E38: ade | F38: 2.4.3 | G38: failed | H38: passed | I38: =IF(EXACT(G38,H38),1,0) -> 0 | J38: 0 | K38: N/A | L38: 0 | M38: 1 | N38: axe-core | O38: 1 | P38: 4.8 | S38: Positive tabindex values disrupt natural focus order | V38: hand-authored from W3C Understanding | X38: corpus1\ade\2.4.3\failed\ha-2-4-3-fail-01-positive-tabindex.html | Y38: Found 1 rule violation(s) affecting 4 element(s).
A39: ha-2-4-3-fail-01-positive-tabindex | B39: axe | C39: A | D39: n/a | E39: ade | F39: 2.4.3 | G39: failed | H39: passed | I39: =IF(EXACT(G39,H39),1,0) -> 0 | J39: 1 | K39: N/A | L39: 0 | M39: 1 | N39: axe-core | O39: 1 | P39: 4.98 | S39: Positive tabindex values disrupt natural focus order | V39: hand-authored from W3C Understanding | X39: corpus1\ade\2.4.3\failed\ha-2-4-3-fail-01-positive-tabindex.html | Y39: Found 1 rule violation(s) affecting 4 element(s).
A40: ha-2-4-3-fail-01-positive-tabindex | B40: axe | C40: A | D40: n/a | E40: ade | F40: 2.4.3 | G40: failed | H40: passed | I40: =IF(EXACT(G40,H40),1,0) -> 0 | J40: 2 | K40: N/A | L40: 0 | M40: 1 | N40: axe-core | O40: 1 | P40: 4.72 | S40: Positive tabindex values disrupt natural focus order | V40: hand-authored from W3C Understanding | X40: corpus1\ade\2.4.3\failed\ha-2-4-3-fail-01-positive-tabindex.html | Y40: Found 1 rule violation(s) affecting 4 element(s).
...

Sheet B_persona_llm
A1: snippet_id | B1: condition | C1: condition_key | D1: model | E1: persona | F1: wcag_criterion | G1: expected | H1: evaluated | I1: correct | J1: repetition | K1: severity | L1: issue_count | M1: tool_call_count | N1: tools_called | O1: iteration_count | P1: total_time_seconds | Q1: input_tokens | R1: output_tokens | S1: testcase_title | T1: rule_id | U1: rule_name | V1: corpus_source | W1: rule_url | X1: html_path | Y1: overall_assessment | Z1: issues_detail
A2: 033e04cced5973596d9aa724feacb027d23b4c53 | B2: persona_llm | C2: B | D2: claude-sonnet-4-6 | E2: ade | F2: 2.1.1 | G2: inapplicable | H2: inapplicable | I2: =IF(EXACT(G2,H2),1,0) -> 1 | J2: 0 | K2: N/A | L2: 0 | M2: 0 | O2: 1 | P2: 3.11 | Q2: 1277 | R2: 91 | S2: Inapplicable Example 2 | T2: akn7bn | U2: Iframe with interactive elements is not excluded from tab-order | W2: https://www.w3.org/WAI/content-assets/wcag-act-rules/testcases/akn7bn/033e04cced5973596d9aa724feacb027d23b4c53.html | X2: corpus1\ade\2.1.1\inapplicable\033e04cced5973596d9aa724feacb027d23b4c53.html | Y2: This page has no visible interactive elements — the only interactive content is an iframe with tabindex='-1' and the hidden attribute, making it completely unreachable and invisible, so there is nothing here for me to navigate to or interact with.
A3: 033e04cced5973596d9aa724feacb027d23b4c53 | B3: persona_llm | C3: B | D3: claude-sonnet-4-6 | E3: ade | F3: 2.1.1 | G3: inapplicable | H3: inapplicable | I3: =IF(EXACT(G3,H3),1,0) -> 1 | J3: 1 | K3: N/A | L3: 0 | M3: 0 | O3: 1 | P3: 2.82 | Q3: 1277 | R3: 92 | S3: Inapplicable Example 2 | T3: akn7bn | U3: Iframe with interactive elements is not excluded from tab-order | W3: https://www.w3.org/WAI/content-assets/wcag-act-rules/testcases/akn7bn/033e04cced5973596d9aa724feacb027d23b4c53.html | X3: corpus1\ade\2.1.1\inapplicable\033e04cced5973596d9aa724feacb027d23b4c53.html | Y3: This page has no visible interactive elements whatsoever — the only interactive content is an iframe with tabindex='-1' and hidden attributes, making it completely unreachable and invisible, so there is nothing here for me to navigate or interact with.
A4: 033e04cced5973596d9aa724feacb027d23b4c53 | B4: persona_llm | C4: B | D4: claude-sonnet-4-6 | E4: ade | F4: 2.1.1 | G4: inapplicable | H4: inapplicable | I4: =IF(EXACT(G4,H4),1,0) -> 1 | J4: 2 | K4: N/A | L4: 0 | M4: 0 | O4: 1 | P4: 2.97 | Q4: 1277 | R4: 90 | S4: Inapplicable Example 2 | T4: akn7bn | U4: Iframe with interactive elements is not excluded from tab-order | W4: https://www.w3.org/WAI/content-assets/wcag-act-rules/testcases/akn7bn/033e04cced5973596d9aa724feacb027d23b4c53.html | X4: corpus1\ade\2.1.1\inapplicable\033e04cced5973596d9aa724feacb027d23b4c53.html | Y4: This page has no visible interactive elements — the only interactive content is an iframe with tabindex='-1' and the hidden attribute, making it completely unreachable and invisible, so there is nothing here for me to navigate or interact with.
A5: 17a371c470316dc29e424101065ebfe9f7b2e990 | B5: persona_llm | C5: B | D5: claude-sonnet-4-6 | E5: ade | F5: 2.1.1 | G5: inapplicable | H5: inapplicable | I5: =IF(EXACT(G5,H5),1,0) -> 1 | J5: 0 | K5: N/A | L5: 0 | M5: 0 | O5: 1 | P5: 3.22 | Q5: 1278 | R5: 95 | S5: Inapplicable Example 5 | T5: akn7bn | U5: Iframe with interactive elements is not excluded from tab-order | W5: https://www.w3.org/WAI/content-assets/wcag-act-rules/testcases/akn7bn/17a371c470316dc29e424101065ebfe9f7b2e990.html | X5: corpus1\ade\2.1.1\inapplicable\17a371c470316dc29e424101065ebfe9f7b2e990.html | Y5: There are no interactive elements reachable by keyboard on this page — the only element is an iframe with tabindex='-1' and the inert attribute, which removes it and its contents entirely from keyboard interaction, so there is nothing here for me to evaluate.
A6: 17a371c470316dc29e424101065ebfe9f7b2e990 | B6: persona_llm | C6: B | D6: claude-sonnet-4-6 | E6: ade | F6: 2.1.1 | G6: inapplicable | H6: inapplicable | I6: =IF(EXACT(G6,H6),1,0) -> 1 | J6: 1 | K6: N/A | L6: 0 | M6: 0 | O6: 1 | P6: 2.83 | Q6: 1278 | R6: 97 | S6: Inapplicable Example 5 | T6: akn7bn | U6: Iframe with interactive elements is not excluded from tab-order | W6: https://www.w3.org/WAI/content-assets/wcag-act-rules/testcases/akn7bn/17a371c470316dc29e424101065ebfe9f7b2e990.html | X6: corpus1\ade\2.1.1\inapplicable\17a371c470316dc29e424101065ebfe9f7b2e990.html | Y6: This page has no interactive elements reachable by keyboard — the only element is an iframe with tabindex='-1' and the inert attribute, making it and its contents completely removed from the tab order and interaction model, so there is nothing here for me to evaluate.
A7: 17a371c470316dc29e424101065ebfe9f7b2e990 | B7: persona_llm | C7: B | D7: claude-sonnet-4-6 | E7: ade | F7: 2.1.1 | G7: inapplicable | H7: inapplicable | I7: =IF(EXACT(G7,H7),1,0) -> 1 | J7: 2 | K7: N/A | L7: 0 | M7: 0 | O7: 1 | P7: 2.9 | Q7: 1278 | R7: 92 | S7: Inapplicable Example 5 | T7: akn7bn | U7: Iframe with interactive elements is not excluded from tab-order | W7: https://www.w3.org/WAI/content-assets/wcag-act-rules/testcases/akn7bn/17a371c470316dc29e424101065ebfe9f7b2e990.html | X7: corpus1\ade\2.1.1\inapplicable\17a371c470316dc29e424101065ebfe9f7b2e990.html | Y7: This page has no interactive elements reachable by keyboard — the only element is an iframe with tabindex='-1' and the inert attribute, making it completely excluded from interaction, so there's nothing here for me to navigate to or operate.
A8: 1e3939d9f8e0f78f9c564ec6feb12cc5635c0acb | B8: persona_llm | C8: B | D8: claude-sonnet-4-6 | E8: ade | F8: 2.1.1 | G8: passed | H8: passed | I8: =IF(EXACT(G8,H8),1,0) -> 1 | J8: 0 | K8: N/A | L8: 0 | M8: 0 | O8: 1 | P8: 4.18 | Q8: 1267 | R8: 78 | S8: Passed Example 1 | T8: akn7bn | U8: Iframe with interactive elements is not excluded from tab-order | W8: https://www.w3.org/WAI/content-assets/wcag-act-rules/testcases/akn7bn/1e3939d9f8e0f78f9c564ec6feb12cc5635c0acb.html | X8: corpus1\ade\2.1.1\passed\1e3939d9f8e0f78f9c564ec6feb12cc5635c0acb.html | Y8: The page contains a single iframe with a native anchor link that is fully keyboard accessible, has a logical focus order, and native browser focus indicators apply — nothing here blocks me from navigating with Tab.
A9: 1e3939d9f8e0f78f9c564ec6feb12cc5635c0acb | B9: persona_llm | C9: B | D9: claude-sonnet-4-6 | E9: ade | F9: 2.1.1 | G9: passed | H9: passed | I9: =IF(EXACT(G9,H9),1,0) -> 1 | J9: 1 | K9: N/A | L9: 0 | M9: 0 | O9: 1 | P9: 4.79 | Q9: 1267 | R9: 92 | S9: Passed Example 1 | T9: akn7bn | U9: Iframe with interactive elements is not excluded from tab-order | W9: https://www.w3.org/WAI/content-assets/wcag-act-rules/testcases/akn7bn/1e3939d9f8e0f78f9c564ec6feb12cc5635c0acb.html | X9: corpus1\ade\2.1.1\passed\1e3939d9f8e0f78f9c564ec6feb12cc5635c0acb.html | Y9: The page contains a single iframe with a standard anchor link that is keyboard focusable, has no timing issues, follows a logical focus order, and while focus visibility depends on the browser default, there are no explicit violations — this page passes all five criteria I evaluate.
A10: 1e3939d9f8e0f78f9c564ec6feb12cc5635c0acb | B10: persona_llm | C10: B | D10: claude-sonnet-4-6 | E10: ade | F10: 2.1.1 | G10: passed | H10: passed | I10: =IF(EXACT(G10,H10),1,0) -> 1 | J10: 2 | K10: N/A | L10: 0 | M10: 0 | O10: 1 | P10: 3.38 | Q10: 1267 | R10: 90 | S10: Passed Example 1 | T10: akn7bn | U10: Iframe with interactive elements is not excluded from tab-order | W10: https://www.w3.org/WAI/content-assets/wcag-act-rules/testcases/akn7bn/1e3939d9f8e0f78f9c564ec6feb12cc5635c0acb.html | X10: corpus1\ade\2.1.1\passed\1e3939d9f8e0f78f9c564ec6feb12cc5635c0acb.html | Y10: The page contains a single iframe with an anchor link that is keyboard focusable, has no timing issues, follows a logical focus order, and while there is no explicit focus style the browser default should apply — overall this page passes all five criteria I evaluate.
A11: 270a22a8e4ce4d9f073e1484a0d807705207a1d7 | B11: persona_llm | C11: B | D11: claude-sonnet-4-6 | E11: ade | F11: 2.1.1 | G11: passed | H11: passed | I11: =IF(EXACT(G11,H11),1,0) -> 1 | J11: 0 | K11: N/A | L11: 0 | M11: 0 | O11: 1 | P11: 4.98 | Q11: 1490 | R11: 119 | S11: Passed Example 2 | T11: 0ssw9k | U11: Scrollable content can be reached with sequential focus navigation | W11: https://www.w3.org/WAI/content-assets/wcag-act-rules/testcases/0ssw9k/270a22a8e4ce4d9f073e1484a0d807705207a1d7.html | X11: corpus1\ade\2.1.1\passed\270a22a8e4ce4d9f073e1484a0d807705207a1d7.html | Y11: This page has a single scrollable section with one link and a paragraph — the link is a standard anchor element that I can reach with Tab, focus is handled by the browser natively, there are no time limits, no focus order issues, and while the link may be inline text (exempt from 2.5.5 target size), everything here works fine for me as a keyboard user.
A12: 270a22a8e4ce4d9f073e1484a0d807705207a1d7 | B12: persona_llm | C12: B | D12: claude-sonnet-4-6 | E12: ade | F12: 2.1.1 | G12: passed | H12: passed | I12: =IF(EXACT(G12,H12),1,0) -> 1 | J12: 1 | K12: N/A | L12: 0 | M12: 0 | O12: 1 | P12: 3.75 | Q12: 1490 | R12: 107 | S12: Passed Example 2 | T12: 0ssw9k | U12: Scrollable content can be reached with sequential focus navigation | W12: https://www.w3.org/WAI/content-assets/wcag-act-rules/testcases/0ssw9k/270a22a8e4ce4d9f073e1484a0d807705207a1d7.html | X12: corpus1\ade\2.1.1\passed\270a22a8e4ce4d9f073e1484a0d807705207a1d7.html | Y12: This page has a single scrollable section with a standard anchor link and paragraph text — the link is keyboard-focusable, there are no time limits, no focus order issues, no missing focus indicators in native rendering, and the link is inline text so target size exceptions apply; everything checks out for me as a keyboard-only user.
A13: 270a22a8e4ce4d9f073e1484a0d807705207a1d7 | B13: persona_llm | C13: B | D13: claude-sonnet-4-6 | E13: ade | F13: 2.1.1 | G13: passed | H13: passed | I13: =IF(EXACT(G13,H13),1,0) -> 1 | J13: 2 | K13: N/A | L13: 0 | M13: 0 | O13: 1 | P13: 4.33 | Q13: 1490 | R13: 122 | S13: Passed Example 2 | T13: 0ssw9k | U13: Scrollable content can be reached with sequential focus navigation | W13: https://www.w3.org/WAI/content-assets/wcag-act-rules/testcases/0ssw9k/270a22a8e4ce4d9f073e1484a0d807705207a1d7.html | X13: corpus1\ade\2.1.1\passed\270a22a8e4ce4d9f073e1484a0d807705207a1d7.html | Y13: This page has a single scrollable section with one link and a paragraph — the link is a standard native anchor element that I can reach with Tab, focus is handled by the browser's default styles, there are no time limits, no focus order issues, and while the target size of the link may be modest it is inline text so it falls under the native/inline exception — overall this page works fine for me.
A14: 5fa34d0a7eea03109cd12c0e7c21fce793c268db | B14: persona_llm | C14: B | D14: claude-sonnet-4-6 | E14: ade | F14: 2.1.1 | G14: failed | H14: inapplicable | I14: =IF(EXACT(G14,H14),1,0) -> 0 | J14: 0 | K14: N/A | L14: 0 | M14: 0 | O14: 1 | P14: 2.97 | Q14: 1458 | R14: 75 | S14: Failed Example 1 | T14: 0ssw9k | U14: Scrollable content can be reached with sequential focus navigation | W14: https://www.w3.org/WAI/content-assets/wcag-act-rules/testcases/0ssw9k/5fa34d0a7eea03109cd12c0e7c21fce793c268db.html | X14: corpus1\ade\2.1.1\failed\5fa34d0a7eea03109cd12c0e7c21fce793c268db.html | Y14: This page has no interactive elements whatsoever — just a scrollable section with a heading and paragraph text — so none of my five keyboard and timing criteria apply here.
A15: 5fa34d0a7eea03109cd12c0e7c21fce793c268db | B15: persona_llm | C15: B | D15: claude-sonnet-4-6 | E15: ade | F15: 2.1.1 | G15: failed | H15: failed | I15: =IF(EXACT(G15,H15),1,0) -> 1 | J15: 1 | K15: critical | L15: 1 | M15: 0 | O15: 1 | P15: 6.09 | Q15: 1458 | R15: 241 | S15: Failed Example 1 | T15: 0ssw9k | U15: Scrollable content can be reached with sequential focus navigation | W15: https://www.w3.org/WAI/content-assets/wcag-act-rules/testcases/0ssw9k/5fa34d0a7eea03109cd12c0e7c21fce793c268db.html | X15: corpus1\ade\2.1.1\failed\5fa34d0a7eea03109cd12c0e7c21fce793c268db.html | Y15: This page fails me completely — there's a scrollable section I can't reach with Tab, so a chunk of the content is locked away and I have no way to read it. | Z15: [2.1.1] As Ade, I cannot reach this scrollable region with Tab at all. The overflowing text is effectively hidden from me — it simply does not exist in my world. Add tabindex="0" to the scrollable <section> element so keyboard users can focus it and scroll with arrow keys.
A16: 5fa34d0a7eea03109cd12c0e7c21fce793c268db | B16: persona_llm | C16: B | D16: claude-sonnet-4-6 | E16: ade | F16: 2.1.1 | G16: failed | H16: failed | I16: =IF(EXACT(G16,H16),1,0) -> 1 | J16: 2 | K16: critical | L16: 1 | M16: 0 | O16: 1 | P16: 6.86 | Q16: 1458 | R16: 300 | S16: Failed Example 1 | T16: 0ssw9k | U16: Scrollable content can be reached with sequential focus navigation | W16: https://www.w3.org/WAI/content-assets/wcag-act-rules/testcases/0ssw9k/5fa34d0a7eea03109cd12c0e7c21fce793c268db.html | X16: corpus1\ade\2.1.1\failed\5fa34d0a7eea03109cd12c0e7c21fce793c268db.html | Y16: This page has a scrollable container that I can't reach with Tab — the content is locked away from me, and since I use the keyboard for everything, that overflow text simply doesn't exist for me. | Z16: [2.1.1] As Ade, I cannot reach this scrollable region with Tab at all — it simply doesn't exist for me. The text is clipped at 100px and I have no way to read the rest of the WCAG abstract without a mouse to scroll it. Add tabindex="0" to the scrollable <section> element so keyboard users can focus it and use arrow keys to scroll: <section tabindex="0" style="height: 100px; width: 500px; overflow-y: scroll">
A17: 62673162e22ee1e95e962522b1d1c3b549dbfc49 | B17: persona_llm | C17: B | D17: claude-sonnet-4-6 | E17: ade | F17: 2.1.1 | G17: failed | H17: failed | I17: =IF(EXACT(G17,H17),1,0) -> 1 | J17: 0 | K17: critical | L17: 2 | M17: 0 | O17: 1 | P17: 11.14 | Q17: 1272 | R17: 444 | S17: Failed Example 1 | T17: akn7bn | U17: Iframe with interactive elements is not excluded from tab-order | W17: https://www.w3.org/WAI/content-assets/wcag-act-rules/testcases/akn7bn/62673162e22ee1e95e962522b1d1c3b549dbfc49.html | X17: corpus1\ade\2.1.1\failed\62673162e22ee1e95e962522b1d1c3b549dbfc49.html | Y17: This page is completely broken for me — the only interactive element, a Home link, is locked inside an iframe with tabindex='-1', which means it literally does not exist as far as my keyboard is concerned. | Z17: [2.1.1] As Ade, I use Tab for everything. If the iframe is excluded from the tab order with tabindex='-1', the Home link inside it simply does not exist for me — I can never reach it by keyboard. Remove tabindex='-1' from the iframe so it enters the natural tab order, or restructure the content so the link is in the main document and reachable via Tab without needing to enter an iframe. || [2.4.7] Even if I could somehow reach the link, there is no focus styling defined anywhere in this page, so I would have no visible indicator of where my keyboard focus is. Add a visible :focus style (e.g., outline: 2px solid #005fcc) for all interactive elements, and ensure those elements are actually reachable by keyboard first.
